Workbook

Sheet Panduan
B1: Belajar Excel untuk Data Analyst
B2: Paket belajar lengkap: dataset contoh, penjelasan fungsi, 48 latihan bertingkat, dan kunci jawaban dengan rumus hidup. Disusun dari peta belajar: IF, DATEDIF, VLOOKUP / HLOOKUP, REPLACE / SUBSTITUTE, UPPER / LOWER / PROPER, CONCAT, TRIM, AVERAGE, COUNT, SUM, MIN / MAX, Charting, dan Pivot Tables.
B4: 1. Isi Workbook
B5: Sheet (klik untuk membuka) | C5: Isi | D5: Dipakai untuk
B6: Penjelasan_Fungsi | C6: 21 entri: sintaks, argumen, contoh rumus hidup, tips dan kesalahan umum | D6: Dibaca sebelum mengerjakan latihan
B7: Data_Penjualan | C7: 60 transaksi penjualan (Jan - Sep 2026) + 6 kolom bantu kosong (kuning) | D7: SUM, AVERAGE, COUNT, MIN/MAX, IF, DATEDIF, VLOOKUP, Chart, Pivot
B8: Master_Produk | C8: 10 produk - tabel referensi VERTIKAL | D8: VLOOKUP
B9: Target_Region | C9: Target, manajer, cabang per region - tabel referensi HORIZONTAL | D9: HLOOKUP
B10: Data_Karyawan | C10: 20 karyawan, data mentah sengaja 'kotor' + 10 kolom bantu kosong (kuning) | D10: TRIM, UPPER/LOWER/PROPER, CONCAT, REPLACE/SUBSTITUTE, DATEDIF
B11: Latihan | C11: 48 soal (Mudah / Sedang / Sulit) + kolom Jawaban Anda | D11: Tempat mengerjakan
B12: Kunci_Jawaban | C12: Rumus jawaban + hasil (dihitung dari data) + penjelasan | D12: Mencocokkan jawaban
B13: Kunci_Kolom_Penjualan | C13: Hasil lengkap kolom bantu Data_Penjualan (60 baris) | D13: Membandingkan kolom bantu Anda baris demi baris
B14: Kunci_Kolom_Karyawan | C14: Hasil lengkap kolom bantu Data_Karyawan (20 baris) | D14: Membandingkan kolom bantu Anda baris demi baris
B15: Kunci_Pivot_Chart | C15: Tabel pembanding PivotTable + 3 grafik contoh | D15: Mengecek hasil Pivot dan Charting
B17: 2. Roadmap Belajar (dari dasar ke lanjutan)
B18: Tahap | C18: Fungsi / Topik | D18: Dataset | E18: Target kemampuan | F18: Estimasi* | G18: No. Latihan
B19: Tahap 1 - Statistik Dasar | C19: SUM, AVERAGE, COUNT, MIN / MAX | D19: Data_Penjualan | E19: Meringkas data: total, rata-rata, jumlah, nilai ekstrem, termasuk versi bersyarat (SUMIFS, COUNTIFS, dst). | F19: 2-3 jam | G19: 1 - 13
B20: Tahap 2 - Pembersihan Teks | C20: TRIM, UPPER / LOWER / PROPER, CONCAT, REPLACE / SUBSTITUTE | D20: Data_Karyawan | E20: Merapikan data mentah: spasi, huruf besar-kecil, gabung kolom, ganti / samarkan teks. | F20: 3-4 jam | G20: 14 - 25
B21: Tahap 3 - Logika & Tanggal | C21: IF, DATEDIF | D21: Data_Penjualan, Data_Karyawan | E21: Membuat klasifikasi otomatis dan menghitung usia, masa kerja, lama proses. | F21: 3-4 jam | G21: 26 - 34
B22: Tahap 4 - Lookup | C22: VLOOKUP, HLOOKUP | D22: Master_Produk, Target_Region | E22: Menggabungkan beberapa tabel: tarik data referensi ke tabel transaksi. | F22: 3 jam | G22: 35 - 41
B23: Tahap 5 - Visualisasi | C23: Charting | D23: Kunci_Pivot_Chart | E23: Memilih jenis grafik yang tepat dan membuat grafik yang mudah dibaca. | F23: 2 jam | G23: 42 - 44
B24: Tahap 6 - Analisis Ringkas | C24: Pivot Tables | D24: Data_Penjualan | E24: Meringkas data besar secara interaktif tanpa rumus: grouping, slicer, sorting. | F24: 3 jam | G24: 45 - 48
B25: *Estimasi waktu hanya perkiraan untuk pemula; sesuaikan dengan kecepatan belajar Anda.
B27: 3. Cara Belajar yang Disarankan
B28: Langkah 1 - Baca entri fungsi di sheet Penjelasan_Fungsi; ubah-ubah argumen pada contoh untuk melihat hasilnya.
B29: Langkah 2 - Buka sheet data, lalu kerjakan soal pada sheet Latihan secara berurutan. Tulis rumus di kolom kuning (kolom bantu) atau di sel kosong.
B30: Langkah 3 - Salin rumus Anda ke kolom 'Jawaban Anda' pada sheet Latihan sebagai catatan.
B31: Langkah 4 - Cocokkan dengan sheet Kunci_Jawaban. Jika berbeda, cek: referensi sel, tanda $ (absolut), tanda kutip, dan urutan argumen.
B32: Langkah 5 - Untuk soal per-baris, bandingkan seluruh kolom bantu Anda dengan sheet Kunci_Kolom_Penjualan / Kunci_Kolom_Karyawan.
B33: Langkah 6 - Ulangi tanpa melihat kunci, lalu coba modifikasi soal (ganti kategori, region, atau nilai ambang) untuk menguji pemahaman.
B35: 4. Legenda Warna
B36: Contoh | C36: Header biru tua = kolom data mentah
B37: Contoh | C37: Header hijau = kolom sudah berisi rumus (contoh: Total_Penjualan)
B38: Contoh | C38: Header emas + sel kuning muda = kolom bantu untuk latihan (sengaja kosong)
B39: Contoh | C39: Sel kuning + huruf biru = input yang boleh diubah (Tanggal_Acuan)
B40: Contoh | C40: Header merah = sheet kunci jawaban
B42: 5. Catatan Penting
B43: - Pemisah argumen: rumus ditulis dengan koma (,). Jika pengaturan regional Excel Anda menolak rumus, ganti koma dengan titik koma (;). Nama fungsi tetap dalam bahasa Inggris.
B44: - CONCAT, MAXIFS, dan MINIFS membutuhkan Excel 2019 / Microsoft 365. Pada Excel lama gunakan operator & atau CONCATENATE (serta rumus array untuk MAXIFS).
B45: - DATEDIF tidak muncul di daftar saran fungsi, tetapi tetap bisa diketik manual. Latihan memakai Tanggal_Acuan tetap (sel V2 di Data_Karyawan) = 26/10/2026 agar hasil konsisten, bukan TODAY().
...

Sheet Penjelasan_Fungsi
A1: Penjelasan Fungsi Excel untuk Data Analyst
A2: Kolom 'Hasil Contoh' dihitung langsung dari dataset di workbook ini (rumus hidup). Urutan dari fungsi dasar ke lanjutan.
A4: No | B4: Fungsi | C4: Level | D4: Kegunaan untuk Data Analyst | E4: Sintaks | F4: Penjelasan Argumen | G4: Contoh Rumus (pada dataset) | H4: Hasil Contoh | I4: Tips & Kesalahan Umum
A5: 1 | B5: SUM | C5: Dasar | D5: Menghitung total: omzet, biaya, jumlah unit. Dasar dari hampir semua laporan. | E5: =SUM(angka1, [angka2], ...) | F5: angka1, angka2, ... = sel, rentang (mis. H2:H61), atau angka langsung. Bisa sampai 255 argumen. | G5: =SUM(Data_Penjualan!$H$2:$H$61) | H5: =SUM(Data_Penjualan!$H$2:$H$61) -> 467 | I5: Teks dan sel kosong diabaikan. Jika hasil 0, cek apakah angka tersimpan sebagai teks (rata kiri, segitiga hijau di pojok sel). Shortcut AutoSum: Alt + =
A6: 2 | B6: SUMIF / SUMIFS | C6: Dasar | D6: Menjumlahkan hanya baris yang memenuhi syarat: omzet per region, per kategori, per sales. | E6: =SUMIF(rentang_kriteria, kriteria, [rentang_jumlah]) =SUMIFS(rentang_jumlah, rentang_kriteria1, kriteria1, ...) | F6: kriteria bisa teks ("Jakarta"), angka, atau operator (">=1000000"). SUMIFS boleh memakai banyak syarat sekaligus (logika AND). | G6: =SUMIF(Data_Penjualan!$F$2:$F$61,"Furniture",Data_Penjualan!$M$2:$M$61) | H6: =SUMIF(Data_Penjualan!$F$2:$F$61,"Furniture",Data_Penjualan!$M$2:$M$61) -> 58050000 | I6: Urutan argumen SUMIF dan SUMIFS BERBEDA (kesalahan paling umum). Semua rentang harus berukuran sama. Operator + sel ditulis: ">="&A1
A7: 3 | B7: AVERAGE | C7: Dasar | D7: Rata-rata: nilai transaksi rata-rata, rata-rata gaji, rata-rata lama pengiriman. | E7: =AVERAGE(angka1, [angka2], ...) =AVERAGEIF(rentang_kriteria, kriteria, [rentang_rata2]) =AVERAGEIFS(rentang_rata2, rentang_kriteria1, kriteria1, ...) | F7: Sel kosong dan teks diabaikan; sel berisi angka 0 tetap dihitung. | G7: =AVERAGE(Data_Penjualan!$H$2:$H$61) | H7: =AVERAGE(Data_Penjualan!$H$2:$H$61) -> 7.7833333 | I7: Rata-rata mudah terdistorsi outlier - bandingkan dengan MEDIAN. AVERAGEIF tanpa baris yang cocok menghasilkan error DIV/0 - bungkus dengan IFERROR.
A8: 4 | B8: COUNT / COUNTA / COUNTBLANK | C8: Dasar | D8: Menghitung jumlah data: jumlah transaksi, pelanggan, dan data kosong (cek kualitas data). | E8: =COUNT(nilai1, ...) =COUNTA(nilai1, ...) =COUNTBLANK(rentang) | F8: COUNT = hanya angka (termasuk tanggal). COUNTA = semua sel tidak kosong (teks dan angka). COUNTBLANK = sel kosong. | G8: =COUNTA(Data_Penjualan!$A$2:$A$61) | H8: =COUNTA(Data_Penjualan!$A$2:$A$61) -> 60 | I8: Gunakan COUNTA pada kolom ID untuk menghitung jumlah baris data. COUNT mengabaikan teks, sehingga cocok untuk mengecek apakah kolom tanggal terisi.
A9: 5 | B9: COUNTIF / COUNTIFS | C9: Dasar | D9: Menghitung baris yang memenuhi syarat: distribusi status, jumlah order besar, dll. | E9: =COUNTIF(rentang, kriteria) =COUNTIFS(rentang1, kriteria1, rentang2, kriteria2, ...) | F9: kriteria sama seperti SUMIF: teks, angka, atau operator (">=5000000"). Wildcard: * (banyak karakter) dan ? (satu karakter). | G9: =COUNTIF(Data_Penjualan!$K$2:$K$61,"Cicilan") | H9: =COUNTIF(Data_Penjualan!$K$2:$K$61,"Cicilan") -> 7 | I9: Spasi tersembunyi di data membuat COUNTIF tidak cocok - bersihkan dengan TRIM dulu. Contoh wildcard: "Toko*" = semua yang diawali Toko.
A10: 6 | B10: MIN | C10: Dasar | D10: Nilai terkecil: harga terendah, gaji terendah, tanggal paling awal (tanggal adalah angka serial). | E10: =MIN(angka1, [angka2], ...) =MINIFS(rentang_min, rentang_kriteria, kriteria) | F10: Sama seperti SUM: menerima sel, rentang, atau angka. Teks dan sel kosong diabaikan. | G10: =MIN(Data_Karyawan!$J$2:$J$21) | H10: =MIN(Data_Karyawan!$J$2:$J$21) -> 6500000 | I10: Berguna untuk mendeteksi data aneh (mis. harga negatif atau 0). Untuk hasil berupa tanggal, ubah format sel menjadi Date. MINIFS butuh Excel 2019 / 365.
A11: 7 | B11: MAX | C11: Dasar | D11: Nilai terbesar: omzet tertinggi, gaji tertinggi, tanggal paling akhir. | E11: =MAX(angka1, [angka2], ...) =MAXIFS(rentang_max, rentang_kriteria, kriteria) | F11: Sama seperti MIN. MAXIFS menambahkan syarat (Excel 2019 / 365). | G11: =MAX(Data_Karyawan!$J$2:$J$21) | H11: =MAX(Data_Karyawan!$J$2:$J$21) -> 25000000 | I11: MAX + MATCH + INDEX = mengambil NAMA pemilik nilai tertinggi. Selisih MAX - MIN = rentang (range) data.
A12: 8 | B12: TRIM | C12: Dasar | D12: Menghapus spasi berlebih di awal, akhir, dan di antara kata (menyisakan satu spasi). Langkah pertama data cleaning. | E12: =TRIM(teks) | F12: teks = sel atau teks yang akan dirapikan. | G12: =TRIM(Data_Karyawan!D2) | H12: =TRIM(Data_Karyawan!D2) -> Sales Executive | I12: TRIM tidak menghapus spasi non-breaking (CHAR(160)) hasil copy dari web: =TRIM(SUBSTITUTE(A1,CHAR(160)," ")). Tanpa TRIM, VLOOKUP dan COUNTIF sering gagal karena spasi tersembunyi.
A13: 9 | B13: UPPER | C13: Dasar | D13: Mengubah semua huruf menjadi KAPITAL: kode produk, kode wilayah, ID. | E13: =UPPER(teks) | F13: teks = sel atau teks yang diubah. | G13: =UPPER(Data_Karyawan!E2) | H13: =UPPER(Data_Karyawan!E2) -> SALES | I13: Berguna untuk menyeragamkan kode sebelum dipakai sebagai kunci lookup.
A14: 10 | B14: LOWER | C14: Dasar | D14: Mengubah semua huruf menjadi huruf kecil: standarisasi email, username, URL. | E14: =LOWER(teks) | F14: teks = sel atau teks yang diubah. | G14: =LOWER(TRIM(Data_Karyawan!I2)) | H14: =LOWER(TRIM(Data_Karyawan!I2)) -> budi.santoso@perusahaan.co.id | I14: Gabungkan dengan TRIM: LOWER(TRIM(...)). Lookup Excel tidak peka huruf besar-kecil, tetapi database / tool lain bisa peka.
A15: 11 | B15: PROPER | C15: Dasar | D15: Mengubah huruf pertama tiap kata menjadi kapital: nama orang, nama kota, judul. | E15: =PROPER(teks) | F15: teks = sel atau teks yang diubah. | G15: =PROPER(TRIM(Data_Karyawan!B2)) | H15: =PROPER(TRIM(Data_Karyawan!B2)) -> Budi | I15: PROPER mengubah "PT" menjadi "Pt" dan "McDonald" menjadi "Mcdonald" - periksa singkatan dan nama khusus secara manual.
A16: 12 | B16: CONCAT | C16: Menengah | D16: Menggabungkan beberapa sel / teks: nama lengkap, kode unik, alamat, label. | E16: =CONCAT(teks1, [teks2], ...) atau operator & | =TEXTJOIN(pemisah, abaikan_kosong, teks1, ...) | F16: Teks literal ditulis dengan tanda kutip, mis. " " untuk spasi. CONCAT menerima rentang (CONCATENATE versi lama tidak). | G16: =CONCAT(PROPER(TRIM(Data_Karyawan!B3))," ",PROPER(TRIM(Data_Karyawan!C3))) | H16: =_xlfn.CONCAT(PROPER(TRIM(Data_Karyawan!B3))," ",PROPER(TRIM(Data_Karyawan!C3))) -> Siti Rahmawati | I16: Operator & setara dan kompatibel semua versi Excel: =A2&" "&B2. Angka / tanggal yang digabung menjadi teks - gunakan TEXT(tanggal,"dd/mm/yyyy") untuk mengatur formatnya.
A17: 13 | B17: REPLACE | C17: Menengah | D17: Mengganti karakter berdasarkan POSISI: masking data, ganti prefix kode, perbaiki format ID. | E17: =REPLACE(teks_lama, posisi_awal, jumlah_karakter, teks_baru) | F17: posisi_awal = karakter ke-n (mulai dari 1). jumlah_karakter = berapa karakter yang diganti. teks_baru = pengganti. | G17: =REPLACE(Data_Karyawan!H3,11,4,"XXXX") | H17: =REPLACE(Data_Karyawan!H3,11,4,"XXXX") -> 0813-5551-XXXX | I17: Jika jumlah_karakter = 0, REPLACE hanya menyisipkan teks tanpa menghapus. Posisi dihitung mulai 1, bukan 0.
A18: 14 | B18: SUBSTITUTE | C18: Menengah | D18: Mengganti TEKS tertentu di mana pun muncul: hapus tanda baca, ganti istilah, bersihkan data. | E18: =SUBSTITUTE(teks, teks_lama, teks_baru, [kemunculan_ke]) | F18: kemunculan_ke (opsional) = hanya ganti kemunculan ke-n; dikosongkan = ganti semua. Peka huruf besar-kecil. | G18: =SUBSTITUTE(Data_Penjualan!A3,"TRX","INV") | H18: =SUBSTITUTE(Data_Penjualan!A3,"TRX","INV") -> INV-0002 | I18: REPLACE mencari berdasarkan posisi, SUBSTITUTE berdasarkan isi teks. Untuk MENGHAPUS teks, isi teks_baru dengan "" (kosong). Bisa disusun bertingkat untuk beberapa karakter.
A19: 15 | B19: IF | C19: Menengah | D19: Membuat keputusan otomatis: klasifikasi (Besar / Kecil), flag data, status. | E19: =IF(uji_logika, nilai_jika_benar, [nilai_jika_salah]) | F19: uji_logika = kondisi dengan operator >, <, >=, <=, =, <>. Teks pada hasil ditulis dengan tanda kutip. | G19: =IF(Data_Penjualan!H2>=10,"Grosir","Eceran") | H19: =IF(Data_Penjualan!H2>=10,"Grosir","Eceran") -> Eceran | I19: Kondisi teks ditulis A2="Lunas" (pakai kutip). <> artinya "tidak sama dengan". Jika nilai_jika_salah dikosongkan dan kondisi salah, hasilnya FALSE.
A20: 16 | B20: IF Bersarang + AND / OR | C20: Lanjut | D20: Klasifikasi lebih dari dua kelas atau kondisi majemuk (mis. prioritas penagihan). | E20: =IF(uji1, hasil1, IF(uji2, hasil2, hasil3)) =IF(AND(kondisi1, kondisi2), ...) =IF(OR(kondisi1, kondisi2), ...) | F20: AND = semua kondisi harus benar. OR = cukup salah satu benar. Pada IF bersarang, urutkan kondisi dari yang paling ketat ke paling longgar. | G20: =IF(AND(Data_Penjualan!J2>0,Data_Penjualan!K2="Lunas"),"Diskon & Lunas","Lainnya") | H20: =IF(AND(Data_Penjualan!J2>0,Data_Penjualan!K2="Lunas"),"Diskon & Lunas","Lainnya") -> Lainnya | I20: Urutan kondisi menentukan hasil. Lebih dari 3-4 level sebaiknya pakai IFS atau tabel lookup. Bungkus IFERROR(rumus, "alternatif") untuk menangani error.
A21: 17 | B21: DATEDIF | C21: Lanjut | D21: Menghitung selisih tanggal dalam tahun / bulan / hari: usia, masa kerja, lama pengiriman, umur piutang. | E21: =DATEDIF(tanggal_awal, tanggal_akhir, satuan) | F21: satuan: "y" = tahun penuh, "m" = bulan penuh, "d" = hari, "ym" = sisa bulan setelah tahun penuh, "md" = sisa hari setelah bulan penuh. | G21: =DATEDIF(Data_Karyawan!G3,Data_Karyawan!$V$2,"y") | H21: =DATEDIF(Data_Karyawan!G3,Data_Karyawan!$V$2,"y") -> 9 | I21: DATEDIF "tersembunyi" (tidak muncul di saran fungsi) tetapi tetap berfungsi. tanggal_awal harus lebih kecil dari tanggal_akhir, jika tidak hasilnya error NUM. Ganti tanggal akhir dengan TODAY() untuk hasil real-time.
A22: 18 | B22: VLOOKUP | C22: Lanjut | D22: Mengambil data dari tabel referensi berdasarkan kunci: menggabungkan data produk, pelanggan, harga ke tabel transaksi. | E22: =VLOOKUP(nilai_dicari, tabel, nomor_kolom, [cocok_persis]) | F22: nilai_dicari = kunci (harus ada di KOLOM PERTAMA tabel). tabel = rentang referensi, kunci absolut ($A$2:$F$11). nomor_kolom = kolom ke-n dalam tabel. cocok_persis = FALSE (atau 0) untuk exact match. | G22: =VLOOKUP("P004",Master_Produk!$A$2:$F$11,2,FALSE) | H22: =VLOOKUP("P004",Master_Produk!$A$2:$F$11,2,FALSE()) -> Mouse Wireless Logitech | I22: Selalu isi FALSE agar exact match. error N/A = kunci tidak ditemukan (cek spasi / tipe data) - tangani dengan IFERROR. Alternatif lebih fleksibel: INDEX + MATCH, atau XLOOKUP (Excel 365).
A23: 19 | B23: HLOOKUP | C23: Lanjut | D23: Sama seperti VLOOKUP, tetapi tabel referensi disusun MENDATAR (judul di baris pertama): target per region, kalender. | E23: =HLOOKUP(nilai_dicari, tabel, nomor_baris, [cocok_persis]) | F23: nilai_dicari dicari di BARIS PERTAMA tabel. nomor_baris = baris ke-n dalam tabel. cocok_persis = FALSE untuk exact match. | G23: =HLOOKUP("Sumatera",Target_Region!$A$1:$F$4,4,FALSE) | H23: =HLOOKUP("Sumatera",Target_Region!$A$1:$F$4,4,FALSE()) -> 3 | I23: Pakai HLOOKUP hanya jika data memang horizontal; data analyst umumnya menyusun data secara vertikal (satu baris = satu record).
A24: 20 | B24: Charting (Grafik) | C24: Menengah | D24: Mengubah angka menjadi visual untuk melihat tren, perbandingan, dan outlier dengan cepat. | E24: Insert > Charts > Column / Line / Pie / Combo | F24: Column / Bar = bandingkan kategori. Line = tren waktu. Pie = proporsi (maks. 5 irisan). Combo = dua ukuran berbeda, mis. realisasi (batang) vs target (garis). | G24: Blok tabel A5:B9 di sheet Kunci_Pivot_Chart > Insert > Clustered Column | H24: Lihat sheet Kunci_Pivot_Chart | I24: Beri judul dan label sumbu, hindari efek 3D, urutkan batang dari terbesar, gunakan satu warna sorot untuk insight utama. Grafik contoh ada di sheet Kunci_Pivot_Chart.
A25: 21 | B25: Pivot Tables | C25: Lanjut | D25: Meringkas ratusan / ribuan baris menjadi tabel ringkasan tanpa rumus. Fondasi analisis ad-hoc. | E25: Insert > PivotTable > pilih tabel > seret field ke Filters / Columns / Rows / Values | F25: Rows = pengelompokan baris. Columns = pengelompokan kolom. Values = angka yang dihitung (Sum, Count, Average, Max, Min). Filters / Slicer = penyaring interaktif. | G25: Rows: Kategori | Values: Sum of Total_Penjualan | H25: =SUM(Data_Penjualan!$M$2:$M$61) -> 434588750 | I25: Data harus rapi: 1 baris header, tanpa baris / kolom kosong, tanpa merge cell. Setelah data berubah klik kanan > Refresh. Field tanggal bisa di-Group per bulan / kuartal / tahun.

Sheet Data_Penjualan
A1: ID_Transaksi | B1: Tgl_Order | C1: Tgl_Kirim | D1: Nama_Pelanggan | E1: Kode_Produk | F1: Kategori | G1: Region | H1: Qty | I1: Harga_Satuan | J1: Diskon | K1: Status_Bayar | L1: Sales_Rep | M1: Total_Penjualan | N1: Nama_Produk | O1: Harga_Pokok | P1: Laba | Q1: Lama_Kirim_Hari | R1: Kelas_Order | S1: Prioritas_Tagih
A2: TRX-0001 | B2: 46028 | C2: 46032 | D2: CV Cahaya Baru | E2: P008 | F2: Furniture | G2: Jawa Timur | H2: 2 | I2: 900000 | J2: 0 | K2: Belum Lunas | L2: Budi Santoso | M2: =H2*I2*(1-J2) -> 1800000
A3: TRX-0002 | B3: 46032 | C3: 46037 | D3: CV Cahaya Baru | E3: P009 | F3: Elektronik | G3: Sumatera | H3: 4 | I3: 2400000 | J3: 0.1 | K3: Cicilan | L3: Dewi Lestari | M3: =H3*I3*(1-J3) -> 8640000
A4: TRX-0003 | B4: 46039 | C4: 46042 | D4: PT Maju Jaya | E4: P007 | F4: Furniture | G4: Jakarta | H4: 7 | I4: 1500000 | J4: 0 | K4: Lunas | L4: Siti Rahmawati | M4: =H4*I4*(1-J4) -> 10500000
A5: TRX-0004 | B5: 46039 | C5: 46042 | D5: PT Nusantara Digital | E5: P010 | F5: ATK | G5: Jawa Tengah | H5: 68 | I5: 55000 | J5: 0.05 | K5: Cicilan | L5: Dewi Lestari | M5: =H5*I5*(1-J5) -> 3553000
A6: TRX-0005 | B6: 46052 | C6: 46057 | D6: CV Cahaya Baru | E6: P008 | F6: Furniture | G6: Jakarta | H6: 5 | I6: 900000 | J6: 0.05 | K6: Belum Lunas | L6: Budi Santoso | M6: =H6*I6*(1-J6) -> 4275000
A7: TRX-0006 | B7: 46066 | C7: 46072 | D7: Koperasi Sejahtera | E7: P006 | F7: Aksesoris | G7: Jawa Tengah | H7: 9 | I7: 480000 | J7: 0 | K7: Lunas | L7: Dewi Lestari | M7: =H7*I7*(1-J7) -> 4320000
A8: TRX-0007 | B8: 46068 | C8: 46069 | D8: CV Cahaya Baru | E8: P003 | F8: Elektronik | G8: Jawa Tengah | H8: 4 | I8: 1800000 | J8: 0.1 | K8: Lunas | L8: Dewi Lestari | M8: =H8*I8*(1-J8) -> 6480000
A9: TRX-0008 | B9: 46072 | C9: 46076 | D9: Toko Sinar Terang | E9: P006 | F9: Aksesoris | G9: Jawa Timur | H9: 3 | I9: 480000 | J9: 0 | K9: Belum Lunas | L9: Andi Pratama | M9: =H9*I9*(1-J9) -> 1440000
A10: TRX-0009 | B10: 46073 | C10: 46080 | D10: CV Berkah Abadi | E10: P002 | F10: Elektronik | G10: Sumatera | H10: 1 | I10: 3200000 | J10: 0.05 | K10: Lunas | L10: Siti Rahmawati | M10: =H10*I10*(1-J10) -> 3040000
A11: TRX-0010 | B11: 46077 | C11: 46082 | D11: UD Sumber Rezeki | E11: P004 | F11: Aksesoris | G11: Jawa Tengah | H11: 8 | I11: 250000 | J11: 0.05 | K11: Lunas | L11: Siti Rahmawati | M11: =H11*I11*(1-J11) -> 1900000
A12: TRX-0011 | B12: 46079 | C12: 46086 | D12: PT Global Teknindo | E12: P001 | F12: Elektronik | G12: Jawa Barat | H12: 3 | I12: 8500000 | J12: 0.1 | K12: Lunas | L12: Siti Rahmawati | M12: =H12*I12*(1-J12) -> 22950000
A13: TRX-0012 | B13: 46079 | C13: 46085 | D13: Koperasi Sejahtera | E13: P008 | F13: Furniture | G13: Jawa Tengah | H13: 5 | I13: 900000 | J13: 0 | K13: Cicilan | L13: Andi Pratama | M13: =H13*I13*(1-J13) -> 4500000
... A57: TRX-0056 | B57: 46286 | C57: 46288 | D57: PT Bintang Utama | E57: P002 | F57: Elektronik | G57: Sumatera | H57: 6 | I57: 3200000 | J57: 0 | K57: Lunas | L57: Siti Rahmawati | M57: =H57*I57*(1-J57) -> 19200000
A58: TRX-0057 | B58: 46289 | D58: Toko Gadget Prima | E58: P003 | F58: Elektronik | G58: Jakarta | H58: 1 | I58: 1800000 | J58: 0 | K58: Lunas | L58: Dewi Lestari | M58: =H58*I58*(1-J58) -> 1800000
A59: TRX-0058 | B59: 46289 | D59: PT Global Teknindo | E59: P005 | F59: Aksesoris | G59: Jawa Timur | H59: 11 | I59: 650000 | J59: 0 | K59: Belum Lunas | L59: Andi Pratama | M59: =H59*I59*(1-J59) -> 7150000
A60: TRX-0059 | B60: 46289 | D60: PT Bintang Utama | E60: P009 | F60: Elektronik | G60: Jawa Tengah | H60: 2 | I60: 2400000 | J60: 0 | K60: Belum Lunas | L60: Andi Pratama | M60: =H60*I60*(1-J60) -> 4800000
A61: TRX-0060 | B61: 46292 | D61: CV Cahaya Baru | E61: P002 | F61: Elektronik | G61: Jawa Barat | H61: 2 | I61: 3200000 | J61: 0.05 | K61: Belum Lunas | L61: Siti Rahmawati | M61: =H61*I61*(1-J61) -> 6080000

Sheet Master_Produk
A1: Kode_Produk | B1: Nama_Produk | C1: Kategori | D1: Harga_Pokok | E1: Supplier | F1: Stok
A2: P001 | B2: Laptop Asus Vivobook 14 | C2: Elektronik | D2: 7200000 | E2: PT Mitra Teknologi | F2: 35
A3: P002 | B3: Smartphone Samsung A15 | C3: Elektronik | D3: 2700000 | E3: PT Samudra Gadget | F3: 80
A4: P003 | B4: Monitor LG 24 inch | C4: Elektronik | D4: 1450000 | E4: PT Mitra Teknologi | F4: 42
A5: P004 | B5: Mouse Wireless Logitech | C5: Aksesoris | D5: 160000 | E5: CV Aksesori Prima | F5: 210
A6: P005 | B6: Keyboard Mekanik Rexus | C6: Aksesoris | D6: 450000 | E6: CV Aksesori Prima | F6: 120
A7: P006 | B7: Headset Gaming Fantech | C7: Aksesoris | D7: 320000 | E7: CV Aksesori Prima | F7: 95
A8: P007 | B8: Kursi Ergonomis Indachi | C8: Furniture | D8: 1000000 | E8: UD Mebel Jaya | F8: 28
A9: P008 | B9: Meja Kerja Lipat | C9: Furniture | D9: 600000 | E9: UD Mebel Jaya | F9: 40
A10: P009 | B10: Printer Epson L3210 | C10: Elektronik | D10: 1950000 | E10: PT Samudra Gadget | F10: 25
A11: P010 | B11: Kertas A4 80gr (Rim) | C11: ATK | D11: 40000 | E11: CV Kertas Nusantara | F11: 600
A13: Catatan: tabel referensi VERTIKAL (kunci di kolom A) untuk latihan VLOOKUP. Data fiktif.

Sheet Target_Region
A1: Region | B1: Jakarta | C1: Jawa Barat | D1: Jawa Tengah | E1: Jawa Timur | F1: Sumatera
A2: Target_Penjualan | B2: 75000000 | C2: 60000000 | D2: 100000000 | E2: 55000000 | F2: 140000000
A3: Manajer_Region | B3: Rudi Hartono | C3: Yuni Astuti | D3: Tono Wibowo | E3: Sari Utami | F3: Bagus Hidayat
A4: Jumlah_Cabang | B4: 4 | C4: 3 | D4: 3 | E4: 2 | F4: 3
A6: Catatan: tabel referensi HORIZONTAL (kunci di baris 1) untuk latihan HLOOKUP. Target dan nama manajer adalah data fiktif (asumsi untuk latihan).

Sheet Data_Karyawan
A1: ID_Karyawan | B1: Nama_Depan | C1: Nama_Belakang | D1: Jabatan | E1: Departemen | F1: Tgl_Lahir | G1: Tgl_Masuk | H1: No_HP | I1: Email | J1: Gaji_Pokok | K1: Nama_Lengkap | L1: Jabatan_Rapi | M1: Email_Rapi | N1: Usia | O1: Masa_Kerja | P1: No_HP_Bersih | Q1: No_HP_Intl | R1: No_HP_Samar | S1: Kode_Baru | T1: Username | V1: Tanggal_Acuan
A2: EMP-001 | B2: budi | C2: santoso | D2: Sales Executive | E2: Sales | F2: 33678 | G2: 43647 | H2: 0812-3456-7801 | I2: Budi.Santoso@Perusahaan.CO.ID | J2: 9500000 | V2: 46321
A3: EMP-002 | B3: SITI | C3: rahmawati | D3: Finance Analyst | E3: Finance | F3: 33179 | G3: 42779 | H3: 0813-5551-0002 | I3: SITI.RAHMAWATI@perusahaan.co.id | J3: 12500000 | V3: Tanggal tetap (input) agar hasil DATEDIF selalu sama.
A4: EMP-003 | B4: andi | C4: PRATAMA | D4: Data Analyst | E4: IT | F4: 34871 | G4: 44200 | H4: 0821-4402-0003 | I4: Andi.Pratama@perusahaan.co.id | J4: 14000000
A5: EMP-004 | B5: dewi | C5: lestari | D5: HR Officer | E5: HR | F5: 34221 | G5: 43241 | H5: 0857-1203-0004 | I5: dewi.lestari@PERUSAHAAN.co.id | J5: 8500000
A6: EMP-005 | B6: Rina | C6: WULANDARI | D6: Marketing Specialist | E6: Marketing | F6: 35094 | G6: 44788 | H6: 0878-9901-0005 | I6: Rina.Wulandari@perusahaan.co.id | J6: 10000000
A7: EMP-006 | B7: agus | C7: setiawan | D7: Sales Executive | E7: Sales | F7: 32854 | G7: 42436 | H7: 0811-2233-0006 | I7: AGUS.SETIAWAN@perusahaan.co.id | J7: 11000000
A8: EMP-007 | B8: PUTRI | C8: anggraini | D8: Accounting Staff | E8: Finance | F8: 35903 | G8: 44977 | H8: 0852-7788-0007 | I8: Putri.Anggraini@Perusahaan.co.id | J8: 7500000
A9: EMP-008 | B9: eko | C9: prasetyo | D9: IT Support | E9: IT | F9: 33475 | G9: 42289 | H9: 0819-6655-0008 | I9: eko.prasetyo@perusahaan.co.id | J9: 9000000
A10: EMP-009 | B10: Maya | C10: Sari | D10: Operations Manager | E10: Operasional | F10: 31904 | G10: 41792 | H10: 0822-3344-0009 | I10: Maya.Sari@perusahaan.co.id | J10: 22000000
A11: EMP-010 | B11: hendra | C11: GUNAWAN | D11: Warehouse Supervisor | E11: Operasional | F11: 32187 | G11: 42632 | H11: 0838-9090-0010 | I11: HENDRA.GUNAWAN@perusahaan.co.id | J11: 13500000
A12: EMP-011 | B12: lina | C12: marlina | D12: Recruiter | E12: HR | F12: 35706 | G12: 45299 | H12: 0856-1010-0011 | I12: lina.marlina@perusahaan.co.id | J12: 7000000
A13: EMP-012 | B13: joko | C13: SUSILO | D13: Sales Manager | E13: Sales | F13: 31257 | G13: 41379 | H13: 0815-4545-0012 | I13: Joko.Susilo@perusahaan.co.id | J13: 24000000
A14: EMP-013 | B14: fitri | C14: handayani | D14: Content Creator | E14: Marketing | F14: 36246 | G14: 45453 | H14: 0877-2020-0013 | I14: FITRI.HANDAYANI@perusahaan.co.id | J14: 7200000
A15: EMP-014 | B15: rizky | C15: Ramadhan | D15: Data Engineer | E15: IT | F15: 34649 | G15: 44137 | H15: 0823-6767-0014 | I15: rizky.ramadhan@perusahaan.co.id | J15: 16500000
... A21: EMP-020 | B21: fajar | C21: Hidayat | D21: HR Manager | E21: HR | F21: 30941 | G21: 41246 | H21: 0818-1414-0020 | I21: fajar.hidayat@perusahaan.co.id | J21: 25000000

Sheet Latihan
A1: Latihan Excel untuk Data Analyst (48 soal)
A2: Kerjakan di sheet data masing-masing (kolom kuning = kolom bantu latihan). Tulis rumus/jawaban Anda di kolom 'Jawaban Anda', lalu cocokkan dengan sheet Kunci_Jawaban.
A4: No | B4: Topik | C4: Level | D4: Soal | E4: Data yang Dipakai | F4: Petunjuk | G4: Jawaban Anda
A5: 1 | B5: SUM | C5: Mudah | D5: Hitung total seluruh penjualan (jumlahkan kolom Total_Penjualan). | E5: Data_Penjualan, kolom M | F5: Gunakan SUM pada rentang M2:M61. Cross-check: blok kolom M dan lihat Sum di status bar. | G5: =SUM(Data_Penjualan!M2:M61) -> 434588750
A6: 2 | B6: SUM | C6: Sedang | D6: Hitung total Qty (jumlah unit) yang terjual untuk kategori "Elektronik". | E6: Data_Penjualan, kolom F dan H | F6: SUMIF(rentang_kriteria, kriteria, rentang_jumlah). Teks kriteria ditulis dengan tanda kutip. | G6: =SUMIF(Data_Penjualan!F2:F61,"Elektronik",Data_Penjualan!H2:H61) -> 100
A7: 3 | B7: SUM | C7: Sulit | D7: Hitung total penjualan untuk Region "Jakarta" yang Status_Bayar-nya "Lunas". | E7: Data_Penjualan, kolom G, K, M | F7: Dua syarat sekaligus = SUMIFS. Argumen pertama SUMIFS adalah rentang yang dijumlahkan. | G7: =SUMIFS(Data_Penjualan!M2:M61,Data_Penjualan!G2:G61,"Jakarta",Data_Penjualan!K2:K61,"Lunas") -> 31398000
A8: 4 | B8: AVERAGE | C8: Mudah | D8: Berapa rata-rata Total_Penjualan per transaksi? | E8: Data_Penjualan, kolom M | F8: AVERAGE pada M2:M61.
A9: 5 | B9: AVERAGE | C9: Sedang | D9: Berapa rata-rata Qty per transaksi untuk kategori "Aksesoris"? | E9: Data_Penjualan, kolom F dan H | F9: AVERAGEIF(rentang_kriteria, kriteria, rentang_rata2).
A10: 6 | B10: AVERAGE | C10: Sulit | D10: Berapa rata-rata Total_Penjualan transaksi milik Sales_Rep "Siti Rahmawati" yang berstatus "Lunas"? | E10: Data_Penjualan, kolom K, L, M | F10: Dua syarat = AVERAGEIFS. Rentang yang dirata-ratakan ditulis PERTAMA.
A11: 7 | B11: COUNT | C11: Mudah | D11: Berapa transaksi yang sudah dikirim (kolom Tgl_Kirim terisi)? | E11: Data_Penjualan, kolom C | F11: Tanggal disimpan sebagai angka, jadi COUNT bisa menghitungnya.
A12: 8 | B12: COUNT | C12: Sedang | D12: Berapa transaksi yang BELUM dikirim (Tgl_Kirim kosong)? Cari dua cara. | E12: Data_Penjualan, kolom A dan C | F12: Cara 1: COUNTBLANK. Cara 2: COUNTA(kolom ID) dikurangi COUNT(kolom Tgl_Kirim).
A13: 9 | B13: COUNT | C13: Sulit | D13: Berapa transaksi di Region "Jawa Timur" dengan Status_Bayar "Belum Lunas"? | E13: Data_Penjualan, kolom G dan K | F13: Dua syarat = COUNTIFS(rentang1, kriteria1, rentang2, kriteria2).
A14: 10 | B14: MIN / MAX | C14: Mudah | D14: Berapa nilai Total_Penjualan terbesar dalam satu transaksi? | E14: Data_Penjualan, kolom M | F14: MAX pada M2:M61.
A15: 11 | B15: MIN / MAX | C15: Mudah | D15: Kapan tanggal order paling awal? (tampilkan dalam format tanggal) | E15: Data_Penjualan, kolom B | F15: MIN pada kolom tanggal, lalu ubah format sel menjadi Date.
A16: 12 | B16: MIN / MAX | C16: Sedang | D16: Berapa selisih antara transaksi terbesar dan terkecil (range data)? | E16: Data_Penjualan, kolom M | F16: Kurangkan MIN dari MAX.
A17: 13 | B17: MIN / MAX | C17: Sulit | D17: Berapa nilai Total_Penjualan terbesar khusus kategori "Furniture"? | E17: Data_Penjualan, kolom F dan M | F17: MAXIFS(rentang_max, rentang_kriteria, kriteria) - butuh Excel 2019 / 365.
A18: 14 | B18: TRIM | C18: Mudah | D18: Rapikan spasi berlebih pada Nama_Depan karyawan di baris 2 (sel B2). | E18: Data_Karyawan, kolom B | F18: =TRIM(B2).
A19: 15 | B19: TRIM | C19: Sedang | D19: Berapa karakter spasi berlebih pada Jabatan di sel D2? (selisih panjang teks sebelum dan sesudah TRIM) | E19: Data_Karyawan, kolom D | F19: LEN(teks) menghitung jumlah karakter. Kurangkan LEN(TRIM(teks)).
... A52: 48 | B52: Pivot Tables | C52: Sulit | D52: Buat PivotTable total penjualan per bulan (Group Tgl_Order by Months) dengan Slicer Status_Bayar. Setelah memilih "Lunas", berapa total penjualan bulan Maret 2026? | E52: Data_Penjualan A1:M61 | F52: Rows = Tgl_Order (klik kanan > Group > Months). PivotTable Analyze > Insert Slicer > Status_Bayar > pilih Lunas.

Sheet Kunci_Jawaban
A1: Kunci Jawaban
A2: Kolom 'Hasil' adalah rumus hidup yang dihitung dari dataset. Soal per-baris dijawab untuk baris 2; hasil seluruh kolom ada di sheet Kunci_Kolom_Penjualan / Kunci_Kolom_Karyawan.
A4: No | B4: Topik | C4: Level | D4: Rumus / Langkah Jawaban | E4: Hasil | F4: Penjelasan
A5: 1 | B5: SUM | C5: Mudah | D5: =SUM(Data_Penjualan!$M$2:$M$61) | E5: =SUM(Data_Penjualan!$M$2:$M$61) -> 434588750 | F5: SUM menjumlahkan semua angka di M2:M61.
A6: 2 | B6: SUM | C6: Sedang | D6: =SUMIF(Data_Penjualan!$F$2:$F$61,"Elektronik",Data_Penjualan!$H$2:$H$61) | E6: =SUMIF(Data_Penjualan!$F$2:$F$61,"Elektronik",Data_Penjualan!$H$2:$H$61) -> 100 | F6: SUMIF memeriksa kolom Kategori (F) lalu hanya menjumlahkan Qty (H) pada baris yang kategorinya Elektronik.
A7: 3 | B7: SUM | C7: Sulit | D7: =SUMIFS(Data_Penjualan!$M$2:$M$61,Data_Penjualan!$G$2:$G$61,"Jakarta",Data_Penjualan!$K$2:$K$61,"Lunas") | E7: =SUMIFS(Data_Penjualan!$M$2:$M$61,Data_Penjualan!$G$2:$G$61,"Jakarta",Data_Penjualan!$K$2:$K$61,"Lunas") -> 31398000 | F7: SUMIFS menjumlahkan M hanya jika Region = Jakarta DAN Status_Bayar = Lunas (logika AND).
A8: 4 | B8: AVERAGE | C8: Mudah | D8: =AVERAGE(Data_Penjualan!$M$2:$M$61) | E8: =AVERAGE(Data_Penjualan!$M$2:$M$61) -> 7243145.8 | F8: AVERAGE = jumlah seluruh nilai dibagi banyaknya nilai (sama dengan SUM / COUNT).
A9: 5 | B9: AVERAGE | C9: Sedang | D9: =AVERAGEIF(Data_Penjualan!$F$2:$F$61,"Aksesoris",Data_Penjualan!$H$2:$H$61) | E9: =AVERAGEIF(Data_Penjualan!$F$2:$F$61,"Aksesoris",Data_Penjualan!$H$2:$H$61) -> 9.7272727 | F9: AVERAGEIF hanya merata-ratakan Qty pada baris berkategori Aksesoris.
A10: 6 | B10: AVERAGE | C10: Sulit | D10: =AVERAGEIFS(Data_Penjualan!$M$2:$M$61,Data_Penjualan!$L$2:$L$61,"Siti Rahmawati",Data_Penjualan!$K$2:$K$61,"Lunas") | E10: =AVERAGEIFS(Data_Penjualan!$M$2:$M$61,Data_Penjualan!$L$2:$L$61,"Siti Rahmawati",Data_Penjualan!$K$2:$K$61,"Lunas") -> 11545455 | F10: AVERAGEIFS menerapkan beberapa syarat (AND) sebelum menghitung rata-rata.
A11: 7 | B11: COUNT | C11: Mudah | D11: =COUNT(Data_Penjualan!$C$2:$C$61) | E11: =COUNT(Data_Penjualan!$C$2:$C$61) -> 56 | F11: COUNT hanya menghitung sel berisi angka / tanggal; sel kosong tidak dihitung.
A12: 8 | B12: COUNT | C12: Sedang | D12: =COUNTBLANK(Data_Penjualan!$C$2:$C$61) | E12: =COUNTBLANK(Data_Penjualan!$C$2:$C$61) -> 4 | F12: Cara lain: =COUNTA(Data_Penjualan!$A$2:$A$61)-COUNT(Data_Penjualan!$C$2:$C$61). Keduanya harus menghasilkan angka sama.
A13: 9 | B13: COUNT | C13: Sulit | D13: =COUNTIFS(Data_Penjualan!$G$2:$G$61,"Jawa Timur",Data_Penjualan!$K$2:$K$61,"Belum Lunas") | E13: =COUNTIFS(Data_Penjualan!$G$2:$G$61,"Jawa Timur",Data_Penjualan!$K$2:$K$61,"Belum Lunas") -> 3 | F13: COUNTIFS menghitung baris yang memenuhi semua syarat sekaligus.
A14: 10 | B14: MIN / MAX | C14: Mudah | D14: =MAX(Data_Penjualan!$M$2:$M$61) | E14: =MAX(Data_Penjualan!$M$2:$M$61) -> 25500000 | F14: MAX mengembalikan angka terbesar pada rentang.
A15: 11 | B15: MIN / MAX | C15: Mudah | D15: =MIN(Data_Penjualan!$B$2:$B$61) | E15: =MIN(Data_Penjualan!$B$2:$B$61) -> 46028 | F15: Tanggal adalah angka serial, sehingga MIN menghasilkan tanggal paling awal. Jika tampil angka besar, ubah Format Cells menjadi Date.
A16: 12 | B16: MIN / MAX | C16: Sedang | D16: =MAX(Data_Penjualan!$M$2:$M$61)-MIN(Data_Penjualan!$M$2:$M$61) | E16: =MAX(Data_Penjualan!$M$2:$M$61)-MIN(Data_Penjualan!$M$2:$M$61) -> 24716250 | F16: Range = MAX - MIN; gambaran sederhana tentang sebaran data.
A17: 13 | B17: MIN / MAX | C17: Sulit | D17: =MAXIFS(Data_Penjualan!$M$2:$M$61,Data_Penjualan!$F$2:$F$61,"Furniture") | E17: =_xlfn.MAXIFS(Data_Penjualan!$M$2:$M$61,Data_Penjualan!$F$2:$F$61,"Furniture") -> 10500000 | F17: MAXIFS = MAX bersyarat. Pada Excel lama, gunakan array: =MAX(IF(F2:F61="Furniture",M2:M61)) dengan Ctrl+Shift+Enter.
A18: 14 | B18: TRIM | C18: Mudah | D18: =TRIM(Data_Karyawan!B2) | E18: =TRIM(Data_Karyawan!B2) -> budi | F18: TRIM menghapus spasi di awal dan akhir teks. Hasil masih huruf kecil - akan dirapikan pada latihan PROPER.
A19: 15 | B19: TRIM | C19: Sedang | D19: =LEN(Data_Karyawan!D2)-LEN(TRIM(Data_Karyawan!D2)) | E19: =LEN(Data_Karyawan!D2)-LEN(TRIM(Data_Karyawan!D2)) -> 5 | F19: LEN asli dikurangi LEN setelah TRIM = jumlah spasi yang dibuang.
A20: 16 | B20: TRIM | C20: Sulit | D20: =SUMPRODUCT(--(LEN(Data_Karyawan!$D$2:$D$21)<>LEN(TRIM(Data_Karyawan!$D$2:$D$21)))) | E20: =SUMPRODUCT(--(LEN(Data_Karyawan!$D$2:$D$21)<>LEN(TRIM(Data_Karyawan!$D$2:$D$21)))) -> 12 | F20: Untuk setiap baris, jika panjang teks asli berbeda dengan panjang setelah TRIM berarti ada spasi berlebih; SUMPRODUCT menjumlahkan semua yang bernilai 1.
A21: 17 | B21: UPPER / LOWER / PROPER | C21: Mudah | D21: =UPPER(Data_Karyawan!E2) | E21: =UPPER(Data_Karyawan!E2) -> SALES | F21: UPPER mengubah setiap huruf menjadi kapital.
A22: 18 | B22: UPPER / LOWER / PROPER | C22: Sedang | D22: =LOWER(TRIM(Data_Karyawan!I2)) | E22: =LOWER(TRIM(Data_Karyawan!I2)) -> budi.santoso@perusahaan.co.id | F22: TRIM bekerja lebih dulu (bagian dalam), lalu LOWER mengubah ke huruf kecil. Seluruh kolom ada di sheet Kunci_Kolom_Karyawan.
A23: 19 | B23: UPPER / LOWER / PROPER | C23: Sedang | D23: =PROPER(TRIM(Data_Karyawan!D2)) | E23: =PROPER(TRIM(Data_Karyawan!D2)) -> Sales Executive | F23: PROPER membuat huruf pertama tiap kata kapital dan sisanya kecil.
A24: 20 | B24: CONCAT | C24: Mudah | D24: =CONCAT(PROPER(TRIM(Data_Karyawan!B2))," ",PROPER(TRIM(Data_Karyawan!C2))) | E24: =_xlfn.CONCAT(PROPER(TRIM(Data_Karyawan!B2))," ",PROPER(TRIM(Data_Karyawan!C2))) -> Budi Santoso | F24: Setara dengan operator &: =PROPER(TRIM(B2))&" "&PROPER(TRIM(C2)).
A25: 21 | B25: CONCAT | C25: Sedang | D25: =LOWER(CONCAT(LEFT(TRIM(Data_Karyawan!B2),1),TRIM(Data_Karyawan!C2))) | E25: =LOWER(_xlfn.CONCAT(LEFT(TRIM(Data_Karyawan!B2),1),TRIM(Data_Karyawan!C2))) -> bsantoso | F25: LEFT mengambil inisial, CONCAT menggabungkan dengan nama belakang, LOWER mengecilkan semua huruf.
A26: 22 | B26: CONCAT | C26: Sedang | D26: =CONCAT(UPPER(LEFT(Data_Karyawan!E2,3)),"-",RIGHT(Data_Karyawan!A2,3)) | E26: =_xlfn.CONCAT(UPPER(LEFT(Data_Karyawan!E2,3)),"-",RIGHT(Data_Karyawan!A2,3)) -> SAL-001 | F26: LEFT mengambil 3 karakter dari kiri, RIGHT 3 karakter dari kanan; UPPER membuat kapital; CONCAT menggabungkan dengan tanda hubung.
A27: 23 | B27: REPLACE / SUBSTITUTE | C27: Mudah | D27: =SUBSTITUTE(Data_Karyawan!H2,"-","") | E27: =SUBSTITUTE(Data_Karyawan!H2,"-","") -> 081234567801 | F27: SUBSTITUTE mengganti SEMUA kemunculan "-" dengan teks kosong.
A28: 24 | B28: REPLACE / SUBSTITUTE | C28: Sedang | D28: =REPLACE(SUBSTITUTE(Data_Karyawan!H2,"-",""),1,1,"+62") | E28: =REPLACE(SUBSTITUTE(Data_Karyawan!H2,"-",""),1,1,"+62") -> +6281234567801 | F28: REPLACE bekerja berdasarkan posisi: mulai dari karakter ke-1, ganti 1 karakter dengan "+62".
A29: 25 | B29: REPLACE / SUBSTITUTE | C29: Sulit | D29: =REPLACE(SUBSTITUTE(Data_Karyawan!H2,"-",""),5,4,"****") | E29: =REPLACE(SUBSTITUTE(Data_Karyawan!H2,"-",""),5,4,"****") -> 0812****7801 | F29: SUBSTITUTE membersihkan tanda "-", lalu REPLACE mengganti 4 karakter mulai posisi ke-5 dengan "****".
A30: 26 | B30: IF | C30: Mudah | D30: =IF(Data_Penjualan!M2>=10000000,"Besar","Kecil") | E30: =IF(Data_Penjualan!M2>=10000000,"Besar","Kecil") -> Kecil | F30: IF menguji kondisi: jika benar tampil "Besar", jika salah "Kecil".
A31: 27 | B31: IF | C31: Sedang | D31: =IF(Data_Penjualan!M2>=20000000,"Besar",IF(Data_Penjualan!M2>=5000000,"Sedang","Kecil")) | E31: =IF(Data_Penjualan!M2>=20000000,"Besar",IF(Data_Penjualan!M2>=5000000,"Sedang","Kecil")) -> Kecil | F31: Kondisi paling ketat (>= 20 juta) dicek lebih dulu. Jika salah, lanjut ke IF kedua. Hasil seluruh kolom ada di sheet Kunci_Kolom_Penjualan.
A32: 28 | B32: IF | C32: Sulit | D32: =IF(AND(Data_Penjualan!K2<>"Lunas",Data_Penjualan!M2>=10000000),"Prioritas Tagih",IF(Data_Penjualan!K2<>"Lunas","Tagih Biasa","Selesai")) | E32: =IF(AND(Data_Penjualan!K2<>"Lunas",Data_Penjualan!M2>=10000000),"Prioritas Tagih",IF(Data_Penjualan!K2<>"Lunas","Tagih Biasa","Selesai")) -> Tagih Biasa | F32: AND menggabungkan dua syarat. Jika gagal, IF kedua memeriksa apakah belum lunas saja.
A33: 29 | B33: IF | C33: Sedang | D33: =COUNTIF(Data_Penjualan!$M$2:$M$61,">=20000000") | E33: =COUNTIF(Data_Penjualan!$M$2:$M$61,">=20000000") -> 4 | F33: Cek silang: hasil ini harus sama dengan jumlah baris "Besar" pada kolom R hasil latihan IF kedua (=COUNTIF(R2:R61,"Besar")).
A34: 30 | B34: DATEDIF | C34: Mudah | D34: =DATEDIF(Data_Karyawan!F2,Data_Karyawan!$V$2,"y") | E34: =DATEDIF(Data_Karyawan!F2,Data_Karyawan!$V$2,"y") -> 34 | F34: Satuan "y" = jumlah tahun penuh antara dua tanggal.
A35: 31 | B35: DATEDIF | C35: Sedang | D35: =DATEDIF(Data_Karyawan!G2,Data_Karyawan!$V$2,"y")&" tahun "&DATEDIF(Data_Karyawan!G2,Data_Karyawan!$V$2,"ym")&" bulan" | E35: =DATEDIF(Data_Karyawan!G2,Data_Karyawan!$V$2,"y")&" tahun "&DATEDIF(Data_Karyawan!G2,Data_Karyawan!$V$2,"ym")&" bulan" -> 7 tahun 3 bulan | F35: "ym" menghitung sisa bulan SETELAH tahun penuh dikeluarkan, sehingga tidak dobel hitung.
A36: 32 | B36: DATEDIF | C36: Sedang | D36: =IF(Data_Penjualan!C2="","Belum dikirim",DATEDIF(Data_Penjualan!B2,Data_Penjualan!C2,"d")) | E36: =IF(Data_Penjualan!C2="","Belum dikirim",DATEDIF(Data_Penjualan!B2,Data_Penjualan!C2,"d")) -> 4 | F36: Tanpa IF, baris yang Tgl_Kirim-nya kosong akan menghasilkan error NUM. Satuan "d" = selisih hari.
A37: 33 | B37: DATEDIF | C37: Sedang | D37: =AVERAGE(Data_Penjualan!$Q$2:$Q$61) | E37: =AVERAGE(Kunci_Kolom_Penjualan!$E$2:$E$61) -> 4.0892857 | F37: Kolom Q berisi angka atau teks; AVERAGE hanya memproses angka. (Pada file ini, hasil membaca kolom yang sama di sheet Kunci_Kolom_Penjualan.)
A38: 34 | B38: DATEDIF | C38: Sulit | D38: =COUNTIF(Data_Karyawan!$G$2:$G$21,"<="&EDATE(Data_Karyawan!$V$2,-60)) | E38: =COUNTIF(Data_Karyawan!$G$2:$G$21,"<="&EDATE(Data_Karyawan!$V$2,-60)) -> 14 | F38: Karyawan bermasa kerja >= 5 tahun = masuk pada atau sebelum tanggal (acuan dikurangi 60 bulan).
A39: 35 | B39: VLOOKUP | C39: Mudah | D39: =VLOOKUP(Data_Penjualan!E2,Master_Produk!$A$2:$F$11,2,FALSE) | E39: =VLOOKUP(Data_Penjualan!E2,Master_Produk!$A$2:$F$11,2,FALSE()) -> Meja Kerja Lipat | F39: Kunci (Kode_Produk) dicari di kolom pertama Master_Produk; angka 2 = ambil kolom ke-2 (Nama_Produk); FALSE = exact match.
A40: 36 | B40: VLOOKUP | C40: Sedang | D40: =VLOOKUP(Data_Penjualan!E2,Master_Produk!$A$2:$F$11,4,FALSE) | E40: =VLOOKUP(Data_Penjualan!E2,Master_Produk!$A$2:$F$11,4,FALSE()) -> 600000 | F40: Rumus sama seperti latihan sebelumnya, hanya nomor kolom diganti 4.
A41: 37 | B41: VLOOKUP | C41: Sedang | D41: =Data_Penjualan!M2-Data_Penjualan!H2*VLOOKUP(Data_Penjualan!E2,Master_Produk!$A$2:$F$11,4,FALSE) | E41: =Data_Penjualan!M2-Data_Penjualan!H2*VLOOKUP(Data_Penjualan!E2,Master_Produk!$A$2:$F$11,4,FALSE()) -> 600000 | F41: Laba = pendapatan bersih (setelah diskon) dikurangi total modal. Jika kolom O sudah ada, cukup =M2-H2*O2.
...

Sheet Kunci_Kolom_Penjualan
A1: ID_Transaksi | B1: Nama_Produk | C1: Harga_Pokok | D1: Laba | E1: Lama_Kirim_Hari | F1: Kelas_Order | G1: Prioritas_Tagih | I1: Kunci kolom bantu N-S pada Data_Penjualan (Nama_Produk s.d. Prioritas_Tagih). Baris sejajar dengan sheet Data_Penjualan. Seluruhnya rumus hidup.
A2: =Data_Penjualan!A2 -> TRX-0001 | B2: =VLOOKUP(Data_Penjualan!E2,Master_Produk!$A$2:$F$11,2,FALSE()) -> Meja Kerja Lipat | C2: =VLOOKUP(Data_Penjualan!E2,Master_Produk!$A$2:$F$11,4,FALSE()) -> 600000 | D2: =Data_Penjualan!M2-Data_Penjualan!H2*C2 -> 600000 | E2: =IF(Data_Penjualan!C2="","Belum dikirim",DATEDIF(Data_Penjualan!B2,Data_Penjualan!C2,"d")) -> 4 | F2: =IF(Data_Penjualan!M2>=20000000,"Besar",IF(Data_Penjualan!M2>=5000000,"Sedang","Kecil")) -> Kecil | G2: =IF(AND(Data_Penjualan!K2<>"Lunas",Data_Penjualan!M2>=10000000),"Prioritas Tagih",IF(Data_Penjualan!K2<>"Lunas","Tagih Biasa","Selesai")) -> Tagih Biasa
A3: =Data_Penjualan!A3 -> TRX-0002 | B3: =VLOOKUP(Data_Penjualan!E3,Master_Produk!$A$2:$F$11,2,FALSE()) -> Printer Epson L3210 | C3: =VLOOKUP(Data_Penjualan!E3,Master_Produk!$A$2:$F$11,4,FALSE()) -> 1950000 | D3: =Data_Penjualan!M3-Data_Penjualan!H3*C3 -> 840000 | E3: =IF(Data_Penjualan!C3="","Belum dikirim",DATEDIF(Data_Penjualan!B3,Data_Penjualan!C3,"d")) -> 5 | F3: =IF(Data_Penjualan!M3>=20000000,"Besar",IF(Data_Penjualan!M3>=5000000,"Sedang","Kecil")) -> Sedang | G3: =IF(AND(Data_Penjualan!K3<>"Lunas",Data_Penjualan!M3>=10000000),"Prioritas Tagih",IF(Data_Penjualan!K3<>"Lunas","Tagih Biasa","Selesai")) -> Tagih Biasa
A4: =Data_Penjualan!A4 -> TRX-0003 | B4: =VLOOKUP(Data_Penjualan!E4,Master_Produk!$A$2:$F$11,2,FALSE()) -> Kursi Ergonomis Indachi | C4: =VLOOKUP(Data_Penjualan!E4,Master_Produk!$A$2:$F$11,4,FALSE()) -> 1000000 | D4: =Data_Penjualan!M4-Data_Penjualan!H4*C4 -> 3500000 | E4: =IF(Data_Penjualan!C4="","Belum dikirim",DATEDIF(Data_Penjualan!B4,Data_Penjualan!C4,"d")) -> 3 | F4: =IF(Data_Penjualan!M4>=20000000,"Besar",IF(Data_Penjualan!M4>=5000000,"Sedang","Kecil")) -> Sedang | G4: =IF(AND(Data_Penjualan!K4<>"Lunas",Data_Penjualan!M4>=10000000),"Prioritas Tagih",IF(Data_Penjualan!K4<>"Lunas","Tagih Biasa","Selesai")) -> Selesai
A5: =Data_Penjualan!A5 -> TRX-0004 | B5: =VLOOKUP(Data_Penjualan!E5,Master_Produk!$A$2:$F$11,2,FALSE()) -> Kertas A4 80gr (Rim) | C5: =VLOOKUP(Data_Penjualan!E5,Master_Produk!$A$2:$F$11,4,FALSE()) -> 40000 | D5: =Data_Penjualan!M5-Data_Penjualan!H5*C5 -> 833000 | E5: =IF(Data_Penjualan!C5="","Belum dikirim",DATEDIF(Data_Penjualan!B5,Data_Penjualan!C5,"d")) -> 3 | F5: =IF(Data_Penjualan!M5>=20000000,"Besar",IF(Data_Penjualan!M5>=5000000,"Sedang","Kecil")) -> Kecil | G5: =IF(AND(Data_Penjualan!K5<>"Lunas",Data_Penjualan!M5>=10000000),"Prioritas Tagih",IF(Data_Penjualan!K5<>"Lunas","Tagih Biasa","Selesai")) -> Tagih Biasa
A6: =Data_Penjualan!A6 -> TRX-0005 | B6: =VLOOKUP(Data_Penjualan!E6,Master_Produk!$A$2:$F$11,2,FALSE()) -> Meja Kerja Lipat | C6: =VLOOKUP(Data_Penjualan!E6,Master_Produk!$A$2:$F$11,4,FALSE()) -> 600000 | D6: =Data_Penjualan!M6-Data_Penjualan!H6*C6 -> 1275000 | E6: =IF(Data_Penjualan!C6="","Belum dikirim",DATEDIF(Data_Penjualan!B6,Data_Penjualan!C6,"d")) -> 5 | F6: =IF(Data_Penjualan!M6>=20000000,"Besar",IF(Data_Penjualan!M6>=5000000,"Sedang","Kecil")) -> Kecil | G6: =IF(AND(Data_Penjualan!K6<>"Lunas",Data_Penjualan!M6>=10000000),"Prioritas Tagih",IF(Data_Penjualan!K6<>"Lunas","Tagih Biasa","Selesai")) -> Tagih Biasa
A7: =Data_Penjualan!A7 -> TRX-0006 | B7: =VLOOKUP(Data_Penjualan!E7,Master_Produk!$A$2:$F$11,2,FALSE()) -> Headset Gaming Fantech | C7: =VLOOKUP(Data_Penjualan!E7,Master_Produk!$A$2:$F$11,4,FALSE()) -> 320000 | D7: =Data_Penjualan!M7-Data_Penjualan!H7*C7 -> 1440000 | E7: =IF(Data_Penjualan!C7="","Belum dikirim",DATEDIF(Data_Penjualan!B7,Data_Penjualan!C7,"d")) -> 6 | F7: =IF(Data_Penjualan!M7>=20000000,"Besar",IF(Data_Penjualan!M7>=5000000,"Sedang","Kecil")) -> Kecil | G7: =IF(AND(Data_Penjualan!K7<>"Lunas",Data_Penjualan!M7>=10000000),"Prioritas Tagih",IF(Data_Penjualan!K7<>"Lunas","Tagih Biasa","Selesai")) -> Selesai
A8: =Data_Penjualan!A8 -> TRX-0007 | B8: =VLOOKUP(Data_Penjualan!E8,Master_Produk!$A$2:$F$11,2,FALSE()) -> Monitor LG 24 inch | C8: =VLOOKUP(Data_Penjualan!E8,Master_Produk!$A$2:$F$11,4,FALSE()) -> 1450000 | D8: =Data_Penjualan!M8-Data_Penjualan!H8*C8 -> 680000 | E8: =IF(Data_Penjualan!C8="","Belum dikirim",DATEDIF(Data_Penjualan!B8,Data_Penjualan!C8,"d")) -> 1 | F8: =IF(Data_Penjualan!M8>=20000000,"Besar",IF(Data_Penjualan!M8>=5000000,"Sedang","Kecil")) -> Sedang | G8: =IF(AND(Data_Penjualan!K8<>"Lunas",Data_Penjualan!M8>=10000000),"Prioritas Tagih",IF(Data_Penjualan!K8<>"Lunas","Tagih Biasa","Selesai")) -> Selesai
A9: =Data_Penjualan!A9 -> TRX-0008 | B9: =VLOOKUP(Data_Penjualan!E9,Master_Produk!$A$2:$F$11,2,FALSE()) -> Headset Gaming Fantech | C9: =VLOOKUP(Data_Penjualan!E9,Master_Produk!$A$2:$F$11,4,FALSE()) -> 320000 | D9: =Data_Penjualan!M9-Data_Penjualan!H9*C9 -> 480000 | E9: =IF(Data_Penjualan!C9="","Belum dikirim",DATEDIF(Data_Penjualan!B9,Data_Penjualan!C9,"d")) -> 4 | F9: =IF(Data_Penjualan!M9>=20000000,"Besar",IF(Data_Penjualan!M9>=5000000,"Sedang","Kecil")) -> Kecil | G9: =IF(AND(Data_Penjualan!K9<>"Lunas",Data_Penjualan!M9>=10000000),"Prioritas Tagih",IF(Data_Penjualan!K9<>"Lunas","Tagih Biasa","Selesai")) -> Tagih Biasa
A10: =Data_Penjualan!A10 -> TRX-0009 | B10: =VLOOKUP(Data_Penjualan!E10,Master_Produk!$A$2:$F$11,2,FALSE()) -> Smartphone Samsung A15 | C10: =VLOOKUP(Data_Penjualan!E10,Master_Produk!$A$2:$F$11,4,FALSE()) -> 2700000 | D10: =Data_Penjualan!M10-Data_Penjualan!H10*C10 -> 340000 | E10: =IF(Data_Penjualan!C10="","Belum dikirim",DATEDIF(Data_Penjualan!B10,Data_Penjualan!C10,"d")) -> 7 | F10: =IF(Data_Penjualan!M10>=20000000,"Besar",IF(Data_Penjualan!M10>=5000000,"Sedang","Kecil")) -> Kecil | G10: =IF(AND(Data_Penjualan!K10<>"Lunas",Data_Penjualan!M10>=10000000),"Prioritas Tagih",IF(Data_Penjualan!K10<>"Lunas","Tagih Biasa","Selesai")) -> Selesai
A11: =Data_Penjualan!A11 -> TRX-0010 | B11: =VLOOKUP(Data_Penjualan!E11,Master_Produk!$A$2:$F$11,2,FALSE()) -> Mouse Wireless Logitech | C11: =VLOOKUP(Data_Penjualan!E11,Master_Produk!$A$2:$F$11,4,FALSE()) -> 160000 | D11: =Data_Penjualan!M11-Data_Penjualan!H11*C11 -> 620000 | E11: =IF(Data_Penjualan!C11="","Belum dikirim",DATEDIF(Data_Penjualan!B11,Data_Penjualan!C11,"d")) -> 5 | F11: =IF(Data_Penjualan!M11>=20000000,"Besar",IF(Data_Penjualan!M11>=5000000,"Sedang","Kecil")) -> Kecil | G11: =IF(AND(Data_Penjualan!K11<>"Lunas",Data_Penjualan!M11>=10000000),"Prioritas Tagih",IF(Data_Penjualan!K11<>"Lunas","Tagih Biasa","Selesai")) -> Selesai
A12: =Data_Penjualan!A12 -> TRX-0011 | B12: =VLOOKUP(Data_Penjualan!E12,Master_Produk!$A$2:$F$11,2,FALSE()) -> Laptop Asus Vivobook 14 | C12: =VLOOKUP(Data_Penjualan!E12,Master_Produk!$A$2:$F$11,4,FALSE()) -> 7200000 | D12: =Data_Penjualan!M12-Data_Penjualan!H12*C12 -> 1350000 | E12: =IF(Data_Penjualan!C12="","Belum dikirim",DATEDIF(Data_Penjualan!B12,Data_Penjualan!C12,"d")) -> 7 | F12: =IF(Data_Penjualan!M12>=20000000,"Besar",IF(Data_Penjualan!M12>=5000000,"Sedang","Kecil")) -> Besar | G12: =IF(AND(Data_Penjualan!K12<>"Lunas",Data_Penjualan!M12>=10000000),"Prioritas Tagih",IF(Data_Penjualan!K12<>"Lunas","Tagih Biasa","Selesai")) -> Selesai
A13: =Data_Penjualan!A13 -> TRX-0012 | B13: =VLOOKUP(Data_Penjualan!E13,Master_Produk!$A$2:$F$11,2,FALSE()) -> Meja Kerja Lipat | C13: =VLOOKUP(Data_Penjualan!E13,Master_Produk!$A$2:$F$11,4,FALSE()) -> 600000 | D13: =Data_Penjualan!M13-Data_Penjualan!H13*C13 -> 1500000 | E13: =IF(Data_Penjualan!C13="","Belum dikirim",DATEDIF(Data_Penjualan!B13,Data_Penjualan!C13,"d")) -> 6 | F13: =IF(Data_Penjualan!M13>=20000000,"Besar",IF(Data_Penjualan!M13>=5000000,"Sedang","Kecil")) -> Kecil | G13: =IF(AND(Data_Penjualan!K13<>"Lunas",Data_Penjualan!M13>=10000000),"Prioritas Tagih",IF(Data_Penjualan!K13<>"Lunas","Tagih Biasa","Selesai")) -> Tagih Biasa
... A61: =Data_Penjualan!A61 -> TRX-0060 | B61: =VLOOKUP(Data_Penjualan!E61,Master_Produk!$A$2:$F$11,2,FALSE()) -> Smartphone Samsung A15 | C61: =VLOOKUP(Data_Penjualan!E61,Master_Produk!$A$2:$F$11,4,FALSE()) -> 2700000 | D61: =Data_Penjualan!M61-Data_Penjualan!H61*C61 -> 680000 | E61: =IF(Data_Penjualan!C61="","Belum dikirim",DATEDIF(Data_Penjualan!B61,Data_Penjualan!C61,"d")) -> Belum dikirim | F61: =IF(Data_Penjualan!M61>=20000000,"Besar",IF(Data_Penjualan!M61>=5000000,"Sedang","Kecil")) -> Sedang | G61: =IF(AND(Data_Penjualan!K61<>"Lunas",Data_Penjualan!M61>=10000000),"Prioritas Tagih",IF(Data_Penjualan!K61<>"Lunas","Tagih Biasa","Selesai")) -> Tagih Biasa

Sheet Kunci_Kolom_Karyawan
A1: ID_Karyawan | B1: Nama_Lengkap | C1: Jabatan_Rapi | D1: Email_Rapi | E1: Usia | F1: Masa_Kerja | G1: No_HP_Bersih | H1: No_HP_Intl | I1: No_HP_Samar | J1: Kode_Baru | K1: Username | M1: Kunci kolom bantu K-T pada Data_Karyawan. Baris sejajar dengan sheet Data_Karyawan. Seluruhnya rumus hidup.
A2: =Data_Karyawan!A2 -> EMP-001 | B2: =_xlfn.CONCAT(PROPER(TRIM(Data_Karyawan!B2))," ",PROPER(TRIM(Data_Karyawan!C2))) -> Budi Santoso | C2: =PROPER(TRIM(Data_Karyawan!D2)) -> Sales Executive | D2: =LOWER(TRIM(Data_Karyawan!I2)) -> budi.santoso@perusahaan.co.id | E2: =DATEDIF(Data_Karyawan!F2,Data_Karyawan!$V$2,"y") -> 34 | F2: =DATEDIF(Data_Karyawan!G2,Data_Karyawan!$V$2,"y")&" tahun "&DATEDIF(Data_Karyawan!G2,Data_Karyawan!$V$2,"ym")&" bulan" -> 7 tahun 3 bulan | G2: =SUBSTITUTE(Data_Karyawan!H2,"-","") -> 081234567801 | H2: =REPLACE(SUBSTITUTE(Data_Karyawan!H2,"-",""),1,1,"+62") -> +6281234567801 | I2: =REPLACE(SUBSTITUTE(Data_Karyawan!H2,"-",""),5,4,"****") -> 0812****7801 | J2: =_xlfn.CONCAT(UPPER(LEFT(Data_Karyawan!E2,3)),"-",RIGHT(Data_Karyawan!A2,3)) -> SAL-001 | K2: =LOWER(_xlfn.CONCAT(LEFT(TRIM(Data_Karyawan!B2),1),TRIM(Data_Karyawan!C2))) -> bsantoso
A3: =Data_Karyawan!A3 -> EMP-002 | B3: =_xlfn.CONCAT(PROPER(TRIM(Data_Karyawan!B3))," ",PROPER(TRIM(Data_Karyawan!C3))) -> Siti Rahmawati | C3: =PROPER(TRIM(Data_Karyawan!D3)) -> Finance Analyst | D3: =LOWER(TRIM(Data_Karyawan!I3)) -> siti.rahmawati@perusahaan.co.id | E3: =DATEDIF(Data_Karyawan!F3,Data_Karyawan!$V$2,"y") -> 35 | F3: =DATEDIF(Data_Karyawan!G3,Data_Karyawan!$V$2,"y")&" tahun "&DATEDIF(Data_Karyawan!G3,Data_Karyawan!$V$2,"ym")&" bulan" -> 9 tahun 8 bulan | G3: =SUBSTITUTE(Data_Karyawan!H3,"-","") -> 081355510002 | H3: =REPLACE(SUBSTITUTE(Data_Karyawan!H3,"-",""),1,1,"+62") -> +6281355510002 | I3: =REPLACE(SUBSTITUTE(Data_Karyawan!H3,"-",""),5,4,"****") -> 0813****0002 | J3: =_xlfn.CONCAT(UPPER(LEFT(Data_Karyawan!E3,3)),"-",RIGHT(Data_Karyawan!A3,3)) -> FIN-002 | K3: =LOWER(_xlfn.CONCAT(LEFT(TRIM(Data_Karyawan!B3),1),TRIM(Data_Karyawan!C3))) -> srahmawati
A4: =Data_Karyawan!A4 -> EMP-003 | B4: =_xlfn.CONCAT(PROPER(TRIM(Data_Karyawan!B4))," ",PROPER(TRIM(Data_Karyawan!C4))) -> Andi Pratama | C4: =PROPER(TRIM(Data_Karyawan!D4)) -> Data Analyst | D4: =LOWER(TRIM(Data_Karyawan!I4)) -> andi.pratama@perusahaan.co.id | E4: =DATEDIF(Data_Karyawan!F4,Data_Karyawan!$V$2,"y") -> 31 | F4: =DATEDIF(Data_Karyawan!G4,Data_Karyawan!$V$2,"y")&" tahun "&DATEDIF(Data_Karyawan!G4,Data_Karyawan!$V$2,"ym")&" bulan" -> 5 tahun 9 bulan | G4: =SUBSTITUTE(Data_Karyawan!H4,"-","") -> 082144020003 | H4: =REPLACE(SUBSTITUTE(Data_Karyawan!H4,"-",""),1,1,"+62") -> +6282144020003 | I4: =REPLACE(SUBSTITUTE(Data_Karyawan!H4,"-",""),5,4,"****") -> 0821****0003 | J4: =_xlfn.CONCAT(UPPER(LEFT(Data_Karyawan!E4,3)),"-",RIGHT(Data_Karyawan!A4,3)) -> IT-003 | K4: =LOWER(_xlfn.CONCAT(LEFT(TRIM(Data_Karyawan!B4),1),TRIM(Data_Karyawan!C4))) -> apratama
A5: =Data_Karyawan!A5 -> EMP-004 | B5: =_xlfn.CONCAT(PROPER(TRIM(Data_Karyawan!B5))," ",PROPER(TRIM(Data_Karyawan!C5))) -> Dewi Lestari | C5: =PROPER(TRIM(Data_Karyawan!D5)) -> Hr Officer | D5: =LOWER(TRIM(Data_Karyawan!I5)) -> dewi.lestari@perusahaan.co.id | E5: =DATEDIF(Data_Karyawan!F5,Data_Karyawan!$V$2,"y") -> 33 | F5: =DATEDIF(Data_Karyawan!G5,Data_Karyawan!$V$2,"y")&" tahun "&DATEDIF(Data_Karyawan!G5,Data_Karyawan!$V$2,"ym")&" bulan" -> 8 tahun 5 bulan | G5: =SUBSTITUTE(Data_Karyawan!H5,"-","") -> 085712030004 | H5: =REPLACE(SUBSTITUTE(Data_Karyawan!H5,"-",""),1,1,"+62") -> +6285712030004 | I5: =REPLACE(SUBSTITUTE(Data_Karyawan!H5,"-",""),5,4,"****") -> 0857****0004 | J5: =_xlfn.CONCAT(UPPER(LEFT(Data_Karyawan!E5,3)),"-",RIGHT(Data_Karyawan!A5,3)) -> HR-004 | K5: =LOWER(_xlfn.CONCAT(LEFT(TRIM(Data_Karyawan!B5),1),TRIM(Data_Karyawan!C5))) -> dlestari
A6: =Data_Karyawan!A6 -> EMP-005 | B6: =_xlfn.CONCAT(PROPER(TRIM(Data_Karyawan!B6))," ",PROPER(TRIM(Data_Karyawan!C6))) -> Rina Wulandari | C6: =PROPER(TRIM(Data_Karyawan!D6)) -> Marketing Specialist | D6: =LOWER(TRIM(Data_Karyawan!I6)) -> rina.wulandari@perusahaan.co.id | E6: =DATEDIF(Data_Karyawan!F6,Data_Karyawan!$V$2,"y") -> 30 | F6: =DATEDIF(Data_Karyawan!G6,Data_Karyawan!$V$2,"y")&" tahun "&DATEDIF(Data_Karyawan!G6,Data_Karyawan!$V$2,"ym")&" bulan" -> 4 tahun 2 bulan | G6: =SUBSTITUTE(Data_Karyawan!H6,"-","") -> 087899010005 | H6: =REPLACE(SUBSTITUTE(Data_Karyawan!H6,"-",""),1,1,"+62") -> +6287899010005 | I6: =REPLACE(SUBSTITUTE(Data_Karyawan!H6,"-",""),5,4,"****") -> 0878****0005 | J6: =_xlfn.CONCAT(UPPER(LEFT(Data_Karyawan!E6,3)),"-",RIGHT(Data_Karyawan!A6,3)) -> MAR-005 | K6: =LOWER(_xlfn.CONCAT(LEFT(TRIM(Data_Karyawan!B6),1),TRIM(Data_Karyawan!C6))) -> rwulandari
A7: =Data_Karyawan!A7 -> EMP-006 | B7: =_xlfn.CONCAT(PROPER(TRIM(Data_Karyawan!B7))," ",PROPER(TRIM(Data_Karyawan!C7))) -> Agus Setiawan | C7: =PROPER(TRIM(Data_Karyawan!D7)) -> Sales Executive | D7: =LOWER(TRIM(Data_Karyawan!I7)) -> agus.setiawan@perusahaan.co.id | E7: =DATEDIF(Data_Karyawan!F7,Data_Karyawan!$V$2,"y") -> 36 | F7: =DATEDIF(Data_Karyawan!G7,Data_Karyawan!$V$2,"y")&" tahun "&DATEDIF(Data_Karyawan!G7,Data_Karyawan!$V$2,"ym")&" bulan" -> 10 tahun 7 bulan | G7: =SUBSTITUTE(Data_Karyawan!H7,"-","") -> 081122330006 | H7: =REPLACE(SUBSTITUTE(Data_Karyawan!H7,"-",""),1,1,"+62") -> +6281122330006 | I7: =REPLACE(SUBSTITUTE(Data_Karyawan!H7,"-",""),5,4,"****") -> 0811****0006 | J7: =_xlfn.CONCAT(UPPER(LEFT(Data_Karyawan!E7,3)),"-",RIGHT(Data_Karyawan!A7,3)) -> SAL-006 | K7: =LOWER(_xlfn.CONCAT(LEFT(TRIM(Data_Karyawan!B7),1),TRIM(Data_Karyawan!C7))) -> asetiawan
A8: =Data_Karyawan!A8 -> EMP-007 | B8: =_xlfn.CONCAT(PROPER(TRIM(Data_Karyawan!B8))," ",PROPER(TRIM(Data_Karyawan!C8))) -> Putri Anggraini | C8: =PROPER(TRIM(Data_Karyawan!D8)) -> Accounting Staff | D8: =LOWER(TRIM(Data_Karyawan!I8)) -> putri.anggraini@perusahaan.co.id | E8: =DATEDIF(Data_Karyawan!F8,Data_Karyawan!$V$2,"y") -> 28 | F8: =DATEDIF(Data_Karyawan!G8,Data_Karyawan!$V$2,"y")&" tahun "&DATEDIF(Data_Karyawan!G8,Data_Karyawan!$V$2,"ym")&" bulan" -> 3 tahun 8 bulan | G8: =SUBSTITUTE(Data_Karyawan!H8,"-","") -> 085277880007 | H8: =REPLACE(SUBSTITUTE(Data_Karyawan!H8,"-",""),1,1,"+62") -> +6285277880007 | I8: =REPLACE(SUBSTITUTE(Data_Karyawan!H8,"-",""),5,4,"****") -> 0852****0007 | J8: =_xlfn.CONCAT(UPPER(LEFT(Data_Karyawan!E8,3)),"-",RIGHT(Data_Karyawan!A8,3)) -> FIN-007 | K8: =LOWER(_xlfn.CONCAT(LEFT(TRIM(Data_Karyawan!B8),1),TRIM(Data_Karyawan!C8))) -> panggraini
A9: =Data_Karyawan!A9 -> EMP-008 | B9: =_xlfn.CONCAT(PROPER(TRIM(Data_Karyawan!B9))," ",PROPER(TRIM(Data_Karyawan!C9))) -> Eko Prasetyo | C9: =PROPER(TRIM(Data_Karyawan!D9)) -> It Support | D9: =LOWER(TRIM(Data_Karyawan!I9)) -> eko.prasetyo@perusahaan.co.id | E9: =DATEDIF(Data_Karyawan!F9,Data_Karyawan!$V$2,"y") -> 35 | F9: =DATEDIF(Data_Karyawan!G9,Data_Karyawan!$V$2,"y")&" tahun "&DATEDIF(Data_Karyawan!G9,Data_Karyawan!$V$2,"ym")&" bulan" -> 11 tahun 0 bulan | G9: =SUBSTITUTE(Data_Karyawan!H9,"-","") -> 081966550008 | H9: =REPLACE(SUBSTITUTE(Data_Karyawan!H9,"-",""),1,1,"+62") -> +6281966550008 | I9: =REPLACE(SUBSTITUTE(Data_Karyawan!H9,"-",""),5,4,"****") -> 0819****0008 | J9: =_xlfn.CONCAT(UPPER(LEFT(Data_Karyawan!E9,3)),"-",RIGHT(Data_Karyawan!A9,3)) -> IT-008 | K9: =LOWER(_xlfn.CONCAT(LEFT(TRIM(Data_Karyawan!B9),1),TRIM(Data_Karyawan!C9))) -> eprasetyo
A10: =Data_Karyawan!A10 -> EMP-009 | B10: =_xlfn.CONCAT(PROPER(TRIM(Data_Karyawan!B10))," ",PROPER(TRIM(Data_Karyawan!C10))) -> Maya Sari | C10: =PROPER(TRIM(Data_Karyawan!D10)) -> Operations Manager | D10: =LOWER(TRIM(Data_Karyawan!I10)) -> maya.sari@perusahaan.co.id | E10: =DATEDIF(Data_Karyawan!F10,Data_Karyawan!$V$2,"y") -> 39 | F10: =DATEDIF(Data_Karyawan!G10,Data_Karyawan!$V$2,"y")&" tahun "&DATEDIF(Data_Karyawan!G10,Data_Karyawan!$V$2,"ym")&" bulan" -> 12 tahun 4 bulan | G10: =SUBSTITUTE(Data_Karyawan!H10,"-","") -> 082233440009 | H10: =REPLACE(SUBSTITUTE(Data_Karyawan!H10,"-",""),1,1,"+62") -> +6282233440009 | I10: =REPLACE(SUBSTITUTE(Data_Karyawan!H10,"-",""),5,4,"****") -> 0822****0009 | J10: =_xlfn.CONCAT(UPPER(LEFT(Data_Karyawan!E10,3)),"-",RIGHT(Data_Karyawan!A10,3)) -> OPE-009 | K10: =LOWER(_xlfn.CONCAT(LEFT(TRIM(Data_Karyawan!B10),1),TRIM(Data_Karyawan!C10))) -> msari
A11: =Data_Karyawan!A11 -> EMP-010 | B11: =_xlfn.CONCAT(PROPER(TRIM(Data_Karyawan!B11))," ",PROPER(TRIM(Data_Karyawan!C11))) -> Hendra Gunawan | C11: =PROPER(TRIM(Data_Karyawan!D11)) -> Warehouse Supervisor | D11: =LOWER(TRIM(Data_Karyawan!I11)) -> hendra.gunawan@perusahaan.co.id | E11: =DATEDIF(Data_Karyawan!F11,Data_Karyawan!$V$2,"y") -> 38 | F11: =DATEDIF(Data_Karyawan!G11,Data_Karyawan!$V$2,"y")&" tahun "&DATEDIF(Data_Karyawan!G11,Data_Karyawan!$V$2,"ym")&" bulan" -> 10 tahun 1 bulan | G11: =SUBSTITUTE(Data_Karyawan!H11,"-","") -> 083890900010 | H11: =REPLACE(SUBSTITUTE(Data_Karyawan!H11,"-",""),1,1,"+62") -> +6283890900010 | I11: =REPLACE(SUBSTITUTE(Data_Karyawan!H11,"-",""),5,4,"****") -> 0838****0010 | J11: =_xlfn.CONCAT(UPPER(LEFT(Data_Karyawan!E11,3)),"-",RIGHT(Data_Karyawan!A11,3)) -> OPE-010 | K11: =LOWER(_xlfn.CONCAT(LEFT(TRIM(Data_Karyawan!B11),1),TRIM(Data_Karyawan!C11))) -> hgunawan
A12: =Data_Karyawan!A12 -> EMP-011 | B12: =_xlfn.CONCAT(PROPER(TRIM(Data_Karyawan!B12))," ",PROPER(TRIM(Data_Karyawan!C12))) -> Lina Marlina | C12: =PROPER(TRIM(Data_Karyawan!D12)) -> Recruiter | D12: =LOWER(TRIM(Data_Karyawan!I12)) -> lina.marlina@perusahaan.co.id | E12: =DATEDIF(Data_Karyawan!F12,Data_Karyawan!$V$2,"y") -> 29 | F12: =DATEDIF(Data_Karyawan!G12,Data_Karyawan!$V$2,"y")&" tahun "&DATEDIF(Data_Karyawan!G12,Data_Karyawan!$V$2,"ym")&" bulan" -> 2 tahun 9 bulan | G12: =SUBSTITUTE(Data_Karyawan!H12,"-","") -> 085610100011 | H12: =REPLACE(SUBSTITUTE(Data_Karyawan!H12,"-",""),1,1,"+62") -> +6285610100011 | I12: =REPLACE(SUBSTITUTE(Data_Karyawan!H12,"-",""),5,4,"****") -> 0856****0011 | J12: =_xlfn.CONCAT(UPPER(LEFT(Data_Karyawan!E12,3)),"-",RIGHT(Data_Karyawan!A12,3)) -> HR-011 | K12: =LOWER(_xlfn.CONCAT(LEFT(TRIM(Data_Karyawan!B12),1),TRIM(Data_Karyawan!C12))) -> lmarlina
